<?xml version="1.0"?>
<robot xmlns:xacro="http://www.ros.org/wiki/xacro">
  <xacro:macro name="caster" params="prefix reflect">
    <link name="${prefix}_caster_link">
      <xacro:mesh_visual name="caster"/>
      <collision>
        <geometry>
          <sphere radius="0.005995"/>
        </geometry>
      </collision>
      <xacro:mesh_inertia mass="0.01" scaling="100" volume="0.899919"
                          x="0.000007" y="0.000028" z="-0.000015"
                          ixx="0.129151" ixy="-0.000001" ixz="0"
                                         iyy="0.129119"  iyz="0.000010"
                                                         izz="0.129104"/>
    </link>

    <!--
        Since the ball caster has three degrees of freedom while continuous
        joint only has one, it is implemented as three separate joints connected
        with dummy links.
    -->
    <xacro:dummy_link name="${prefix}_caster_x_to_y_link"/>

    <joint name="${prefix}_caster_x_joint" type="continuous">
      <parent link="base_link"/>
      <origin xyz="${reflect * 0.049191} 0 -0.036909"/>
      <axis xyz="1 0 0"/>
      <child link="${prefix}_caster_x_to_y_link"/>
    </joint>

    <xacro:dummy_link name="${prefix}_caster_y_to_z_link"/>

    <joint name="${prefix}_caster_y_joint" type="continuous">
      <parent link="${prefix}_caster_x_to_y_link"/>
      <axis xyz="0 1 0"/>
      <child link="${prefix}_caster_y_to_z_link"/>
    </joint>

    <joint name="${prefix}_caster_z_joint" type="continuous">
      <parent link="${prefix}_caster_y_to_z_link"/>
      <axis xyz="0 0 1"/>
      <child link="${prefix}_caster_link"/>
    </joint>
  </xacro:macro>
</robot>
