<?xml version="1.0"?>
<robot xmlns:xacro="http://www.ros.org/wiki/xacro">
  <xacro:macro name="wheel" params="prefix reflect">
    <link name="${prefix}_wheel_link">
      <xacro:mesh_visual name="wheel"/>
      <collision>
        <origin xyz="0.000998 0.000001 -0.000002" rpy="0 ${pi / 2} 0"/>
        <geometry>
          <cylinder radius="0.022131" length="0.017986"/>
        </geometry>
      </collision>
      <xacro:mesh_inertia mass="0.03" scaling="10" volume="0.015398"
                          x="0.010317" y="-0.000083" z="-0.000017"
                          ixx="0.000466" ixy="0"         ixz="0"
                                         iyy="0.000272"  iyz="0"
                                                         izz="0.000272"/>
    </link>

    <joint name="${prefix}_wheel_joint" type="continuous">
      <parent link="base_link"/>
      <origin xyz="0.00002 ${reflect * 0.042459} -0.020922"
              rpy="0 0 ${reflect * pi / 2}"/>
      <axis xyz="${reflect} 0 0"/>
      <child link="${prefix}_wheel_link"/>
    </joint>

    <transmission name="${prefix}_wheel_transmission">
      <type>transmission_interface/SimpleTransmission</type>
      <actuator name="${prefix}_wheel_actuator"/>
      <joint name="${prefix}_wheel_joint">
        <hardwareInterface>hardware_interface/VelocityJointInterface</hardwareInterface>
      </joint>
    </transmission>
  </xacro:macro>
</robot>
